<?xml version="1.0"?>
<robot xmlns:xacro="http://www.ros.org/wiki/xacro" name="smart_robot">

    <!-- ================== CONSTANTS & MACROS ================== -->
    <xacro:property name="PI" value="3.1415926535897931"/>

    <xacro:macro name="box_inertia" params="m x y z"><inertia ixx="${m*(y*y+z*z)/12}" ixy="0" ixz="0" iyy="${m*(x*x+z*z)/12}" iyz="0" izz="${m*(x*x+y*y)/12}"/></xacro:macro>
    <xacro:macro name="cylinder_inertia" params="m r h"><inertia ixx="${m*(3*r*r+h*h)/12}" ixy="0" ixz="0" iyy="${m*(3*r*r+h*h)/12}" iyz="0" izz="${m*r*r/2}"/></xacro:macro>
    <xacro:macro name="sphere_inertia" params="m r"><inertia ixx="${2*m*r*r/5}" ixy="0" ixz="0" iyy="${2*m*r*r/5}" iyz="0" izz="${2*m*r*r/5}"/></xacro:macro>
    <xacro:macro name="wheel_inertia" params="m r h"><inertia ixx="${m*(3*r*r+h*h)/12}" ixy="0" ixz="0" iyy="${m*r*r/2}" iyz="0" izz="${m*(3*r*r+h*h)/12}"/></xacro:macro>
    
    <!-- ================== MATERIALS ================== -->
    <material name="blue">
        <color rgba="0 0 0.8 1"/>
    </material>
    <material name="black">
        <color rgba="0 0 0 1"/>
    </material>
    <material name="white">
        <color rgba="1 1 1 1"/>
    </material>
    <material name="green">
        <color rgba="0.1 0.8 0.1 1"/>
    </material>

    <!-- ================== ROBOT STRUCTURE ================== -->

    <!-- Base Link -->
    <link name="base_footprint"/>
    <joint name="base_footprint_joint" type="fixed">
        <parent link="base_footprint"/>
        <child link="base_link"/>
        <origin xyz="0 0 0.4" rpy="0 0 0"/>
    </joint>

    <link name="base_link">
        <visual>
            <geometry><cylinder length="0.6" radius="0.2"/></geometry>
            <material name="blue"/>
        </visual>
        <collision>
            <geometry><cylinder length="0.6" radius="0.2"/></geometry>
        </collision>
        <inertial>
            <mass value="10.0"/>
            <xacro:cylinder_inertia m="10.0" r="0.2" h="0.6"/>
        </inertial>
    </link>

    <!-- Head -->
    <link name="head">
        <visual>
            <geometry><sphere radius="0.2"/></geometry>
            <material name="white"/>
        </visual>
        <collision>
            <geometry><sphere radius="0.2"/></geometry>
        </collision>
        <inertial>
            <mass value="1.0"/>
            <xacro:sphere_inertia m="1.0" r="0.2"/>
        </inertial>
    </link>
    <joint name="head_swivel" type="fixed">
        <parent link="base_link"/>
        <child link="head"/>
        <origin xyz="0 0 0.3"/>
    </joint>

    <!-- Legs and Wheels -->
    <!-- Right Side -->
    <link name="right_leg">
        <visual>
            <geometry><box size="0.6 0.1 0.2"/></geometry>
            <origin rpy="0 1.57075 0" xyz="0 0 -0.3"/>
            <material name="white"/>
        </visual>
        <collision>
            <geometry><box size="0.6 0.1 0.2"/></geometry>
            <origin rpy="0 1.57075 0" xyz="0 0 -0.3"/>
        </collision>
        <inertial>
            <mass value="1.5"/>
            <xacro:box_inertia m="1.5" x="0.2" y="0.1" z="0.6"/>
        </inertial>
    </link>
    <joint name="base_to_right_leg" type="fixed">
        <parent link="base_link"/>
        <child link="right_leg"/>
        <origin xyz="0 -0.22 0.25"/>
    </joint>

    <link name="right_base">
        <visual>
            <geometry><box size="0.4 0.1 0.1"/></geometry>
            <material name="white"/>
        </visual>
        <collision>
            <geometry><box size="0.4 0.1 0.1"/></geometry>
        </collision>
        <inertial>
            <mass value="1.0"/>
            <xacro:box_inertia m="1.0" x="0.4" y="0.1" z="0.1"/>
        </inertial>
    </link>
    <joint name="right_base_joint" type="fixed">
        <parent link="right_leg"/>
        <child link="right_base"/>
        <origin xyz="0 0 -0.6"/>
    </joint>

    <link name="right_front_wheel">
        <visual><origin rpy="1.57075 0 0"/><geometry><cylinder length="0.1" radius="0.035"/></geometry><material name="black"/></visual>
        <collision><origin rpy="1.57075 0 0"/><geometry><cylinder length="0.1" radius="0.035"/></geometry></collision>
        <inertial><mass value="0.2"/><xacro:wheel_inertia m="0.2" r="0.035" h="0.1"/></inertial>
    </link>
    <joint name="right_front_wheel_joint" type="continuous"><parent link="right_base"/><child link="right_front_wheel"/><origin xyz="0.18 0 -0.085"/><axis xyz="0 1 0"/></joint>

    <link name="right_back_wheel">
        <visual><origin rpy="1.57075 0 0"/><geometry><cylinder length="0.1" radius="0.035"/></geometry><material name="black"/></visual>
        <collision><origin rpy="1.57075 0 0"/><geometry><cylinder length="0.1" radius="0.035"/></geometry></collision>
        <inertial><mass value="0.2"/><xacro:wheel_inertia m="0.2" r="0.035" h="0.1"/></inertial>
    </link>
    <joint name="right_back_wheel_joint" type="continuous"><parent link="right_base"/><child link="right_back_wheel"/><origin xyz="-0.18 0 -0.085"/><axis xyz="0 1 0"/></joint>

    <!-- Left Side -->
    <link name="left_leg">
        <visual><geometry><box size="0.6 0.1 0.2"/></geometry><origin rpy="0 1.57075 0" xyz="0 0 -0.3"/><material name="white"/></visual>
        <collision><geometry><box size="0.6 0.1 0.2"/></geometry><origin rpy="0 1.57075 0" xyz="0 0 -0.3"/></collision>
        <inertial><mass value="1.5"/><xacro:box_inertia m="1.5" x="0.2" y="0.1" z="0.6"/></inertial>
    </link>
    <joint name="base_to_left_leg" type="fixed"><parent link="base_link"/><child link="left_leg"/><origin xyz="0 0.22 0.25"/></joint>

    <link name="left_base">
        <visual><geometry><box size="0.4 0.1 0.1"/></geometry><material name="white"/></visual>
        <collision><geometry><box size="0.4 0.1 0.1"/></geometry></collision>
        <inertial><mass value="1.0"/><xacro:box_inertia m="1.0" x="0.4" y="0.1" z="0.1"/></inertial>
    </link>
    <joint name="left_base_joint" type="fixed"><parent link="left_leg"/><child link="left_base"/><origin xyz="0 0 -0.6"/></joint>

    <link name="left_front_wheel">
        <visual><origin rpy="1.57075 0 0"/><geometry><cylinder length="0.1" radius="0.035"/></geometry><material name="black"/></visual>
        <collision><origin rpy="1.57075 0 0"/><geometry><cylinder length="0.1" radius="0.035"/></geometry></collision>
        <inertial><mass value="0.2"/><xacro:wheel_inertia m="0.2" r="0.035" h="0.1"/></inertial>
    </link>
    <joint name="left_front_wheel_joint" type="continuous"><parent link="left_base"/><child link="left_front_wheel"/><origin xyz="0.18 0 -0.085"/><axis xyz="0 1 0"/></joint>

    <link name="left_back_wheel">
        <visual><origin rpy="1.57075 0 0"/><geometry><cylinder length="0.1" radius="0.035"/></geometry><material name="black"/></visual>
        <collision><origin rpy="1.57075 0 0"/><geometry><cylinder length="0.1" radius="0.035"/></geometry></collision>
        <inertial><mass value="0.2"/><xacro:wheel_inertia m="0.2" r="0.035" h="0.1"/></inertial>
    </link>
    <joint name="left_back_wheel_joint" type="continuous"><parent link="left_base"/><child link="left_back_wheel"/><origin xyz="-0.18 0 -0.085"/><axis xyz="0 1 0"/></joint>

    <link name="sprayer_pole">
        <visual>
            <geometry><cylinder length="0.2" radius="0.01"/></geometry>
            <origin rpy="0 1.57075 0" xyz="0.1 0 0"/>
            <material name="black"/>
        </visual>
        <collision><geometry><cylinder length="0.2" radius="0.01"/></geometry><origin rpy="0 1.57075 0" xyz="0.1 0 0"/></collision>
        <inertial><mass value="0.1"/><xacro:cylinder_inertia m="0.1" r="0.01" h="0.2"/></inertial>
    </link>
    <joint name="base_to_sprayer_pole" type="fixed">
        <parent link="base_link"/>
        <child link="sprayer_pole"/>
        <origin rpy="0 0 0" xyz="0.19 0 0.2"/>
    </joint>

    <link name="sprayer_nozzle">
        <visual>
            <geometry><box size="0.04 0.06 0.04"/></geometry>
            <material name="green"/>
        </visual>
        <collision><geometry><box size="0.04 0.06 0.04"/></geometry></collision>
        <inertial><mass value="0.05"/><xacro:box_inertia m="0.05" x="0.04" y="0.06" z="0.04"/></inertial>
    </link>
    <joint name="sprayer_pole_to_nozzle" type="fixed">
        <parent link="sprayer_pole"/>
        <child link="sprayer_nozzle"/>
        <origin xyz="0.22 0 0"/>
    </joint>

    <link name="laser_link">
        <visual><geometry><box size="0.05 0.05 0.05"/></geometry><material name="red"><color rgba="1 0 0 1"/></material></visual>
        <collision><geometry><box size="0.05 0.05 0.05"/></geometry></collision>
        <inertial><mass value="0.1"/><xacro:box_inertia m="0.1" x="0.05" y="0.05" z="0.05"/></inertial>
    </link>
    <joint name="base_to_laser" type="fixed">
        <parent link="base_link"/>
        <child link="laser_link"/>
        <origin xyz="0.2 0 0"/>
    </joint>


    <!-- ================== GAZEBO PLUGINS ================== -->

    <!-- Differential Drive Plugin -->
    <gazebo>
        <plugin name="differential_drive_controller" filename="libgazebo_ros_diff_drive.so">
            <alwaysOn>true</alwaysOn>
            <updateRate>100</updateRate>
            <robotNamespace>/</robotNamespace>
            <leftJoint>left_front_wheel_joint</leftJoint>
            <leftJoint>left_back_wheel_joint</leftJoint>
            <rightJoint>right_front_wheel_joint</rightJoint>
            <rightJoint>right_back_wheel_joint</rightJoint>
            <wheelSeparation>${2 * 0.22}</wheelSeparation>
            <wheelDiameter>${2 * 0.035}</wheelDiameter>
            <wheelTorque>30</wheelTorque>
            <wheelAcceleration>1.8</wheelAcceleration>
            <commandTopic>cmd_vel</commandTopic>
            <odometryTopic>odom</odometryTopic>
            <odometryFrame>odom</odometryFrame>
            <robotBaseFrame>base_footprint</robotBaseFrame>
            <publishTF>1</publishTF>
            <publishWheelJointState>true</publishWheelJointState>
            <odometrySource>world</odometrySource> 
            <legacyMode>false</legacyMode>
            <rosDebugLevel>na</rosDebugLevel>
        </plugin>
    </gazebo>

    <!-- Laser Plugin -->
    <gazebo reference="laser_link">
        <sensor type="ray" name="hokuyo_sensor">
            <pose>0 0 0 0 0 0</pose>
            <visualize>true</visualize>
            <update_rate>20</update_rate>
            <ray>
                <scan>
                    <horizontal>
                        <samples>360</samples>
                        <resolution>1</resolution>
                        <min_angle>-3.14</min_angle>
                        <max_angle>3.14</max_angle>
                    </horizontal>
                </scan>
                <range>
                    <min>0.10</min>
                    <max>10.0</max>
                </range>
            </ray>
            <plugin name="gazebo_ros_laser" filename="libgazebo_ros_laser.so">
                <topicName>/scan</topicName>
                <frameName>laser_link</frameName>
            </plugin>
        </sensor>
    </gazebo>

</robot>